<?xml version="1.0"?>

<robot name="4Armdrone"  xmlns:xacro="http://www.ros.org/wiki/xacro">

  <material name="blue">
    <color rgba="0 0 0.8 1"/>
  </material>

<xacro:property name='sktX' value="0.19674"/>
<xacro:property name='sktY' value="0.09329"/>
<xacro:property name="xd"   value="${-sktX/2}"/>
<xacro:property name="yd"   value="${sktY/2}"/>

<xacro:property name="arm_junction" value="0.0293"/>
<xacro:property name="arm_base" value="0.035"/>
<xacro:property name="arm_ang" value="0.5788"/>
<xacro:property name="arm_len" value="0.155"/>



  <link name="drone">
    
    <visual name="drone_visual">
      <origin xyz="${xd} ${yd} 0" rpy="1.57079 0 0"/>
      <geometry>
        <mesh filename="package://projet_robo_redev/meshes/Gazebo_Base_Body.stl"
              scale="0.001 0.001 0.001" />
      </geometry>
     <material name="blue"/>
    </visual>

    <collision>
      <origin xyz="${xd} ${yd} 0" rpy="1.57079 0 0"/>
      <geometry>
        <mesh filename="package://projet_robo_redev/meshes/Gazebo_Base_Body.stl"
              scale="0.001 0.001 0.001" />
      </geometry>
    </collision>

  </link>

  <link name="arm_1">

    <visual name="arm_1_link_visual">
      <geometry>
        <mesh filename="package://projet_robo_redev/meshes/Gazebo_Base_arm.stl"
              scale="0.001 0.001 0.001"/>
      </geometry>
      <origin xyz="0 ${0} 0"/>
    </visual>

    <collision>
      <geometry>
        <mesh filename="package://projet_robo_redev/meshes/Gazebo_Base_arm.stl"
              scale="0.001 0.001 0.001"/>
      </geometry>
      <origin xyz="0 ${0} 0"/>
    </collision>

  </link>  

  <link name="arm_2">

    <visual name="arm_2_link_visual">
      <geometry>
      <mesh filename="package://projet_robo_redev/meshes/Gazebo_Base_arm.stl"
            scale="0.001 0.001 0.001"/>
      </geometry>
      <origin xyz="0 ${-arm_base} 0"/>
    </visual>

    <collision>
      <origin xyz="0 ${-arm_base} 0"/>
      <geometry>
        <mesh filename="package://projet_robo_redev/meshes/Gazebo_Base_arm.stl"
              scale="0.001 0.001 0.001"/>
      </geometry>

    </collision>
  </link>  

  <link name="arm_3">

    <visual name="arm_3_link_visual">
      <geometry>
        <mesh filename="package://projet_robo_redev/meshes/Gazebo_Base_arm.stl"
              scale="0.001 0.001 0.001"/>
      </geometry>
      <origin xyz="0 ${0} 0"/>
    </visual>

    <collision>
      <geometry>
        <mesh filename="package://projet_robo_redev/meshes/Gazebo_Base_arm.stl"
              scale="0.001 0.001 0.001"/>
      </geometry>
      <origin xyz="0 ${0} 0"/>
    </collision>

  </link>  

  <link name="arm_4">

    <visual name="arm_4_link_visual">
      <geometry>
        <mesh filename="package://projet_robo_redev/meshes/Gazebo_Base_arm.stl"
              scale="0.001 0.001 0.001"/>
      </geometry>
      <origin xyz="0 ${-arm_base} 0"/>
    </visual>

    <collision>
      <geometry>
        <mesh filename="package://projet_robo_redev/meshes/Gazebo_Base_arm.stl"
              scale="0.001 0.001 0.001"/>
      </geometry>
      <origin xyz="0 ${-arm_base} 0"/>

    </collision>

  </link>  


  <joint name="base_to_arm_1" type="revolute">
    <parent link="drone"/>
    <child link="arm_1"/>
    <origin  rpy="0 0 ${pi/2+arm_ang}" xyz="${xd+arm_junction} ${yd} 0"/>
    <axis xyz="0.0 1.0 0.0"/>
    <limit effort="1000.0" lower="0.0" upper="1.74" velocity="1000.0"/>
  </joint>

  <joint name="base_to_arm_2" type="revolute">
    <parent link="drone"/>
    <child link="arm_2"/>
    <origin  rpy="0 0 -${pi/2+arm_ang}" xyz="${xd+arm_junction} ${-yd} 0"/>
    <axis xyz="0.0 1.0 0.0"/>
    <limit effort="1000.0" lower="0.0" upper="1.74" velocity="1000.0"/>
  </joint>

  <joint name="base_to_arm_3" type="revolute">
    <parent link="drone"/>
    <child link="arm_3"/>
    <origin  rpy="0 0 -${pi/2-arm_ang}" xyz="${-xd-arm_junction} ${-yd} 0"/>
    <axis xyz="0.0 1.0 0.0"/>
    <limit effort="1000.0" lower="0.0" upper="1.74" velocity="1000.0"/>
  </joint>


  <joint name="base_to_arm_4" type="revolute">
    <parent link="drone"/>
    <child link="arm_4"/>
    <origin  rpy="0 0 ${pi/2-arm_ang}" xyz="${-xd-arm_junction} ${yd} 0"/>
    <axis xyz="0.0 1.0 0.0"/>
    <limit effort="1000.0" lower="0.0" upper="1.74" velocity="1000.0"/>
  </joint>


  <link name="prop_1">
    <visual name="prop_1_link_visual">
      <geometry>
        <mesh filename="package://projet_robo_redev/meshes/1345_prop_ccw.stl"/>
      </geometry>
      <origin  rpy="0 0 0" xyz="-0.03 -0.17 0"/>
    </visual> 
  </link> 

  <joint name="prop_to_arm_1" type="continuous">
    <parent link="arm_1"/>
    <child link="prop_1"/>
    <origin  rpy="0 0 0" xyz="${arm_len} ${arm_base/2} ${0}"/>
    <axis xyz="0.0 0.0 1"/>
  </joint>

  <link name="prop_2">
    <visual name="prop_2_link_visual">
      <geometry>
        <mesh filename="package://projet_robo_redev/meshes/1345_prop_cw.stl"/>
      </geometry>
      <origin  rpy="0 0 0" xyz="-0.03 -0.17 0"/>
    </visual>
  </link> 

  <joint name="prop_to_arm_2" type="continuous">
    <parent link="arm_2"/>
    <child link="prop_2"/>
    <origin  rpy="0 0 0" xyz="${arm_len} ${-arm_base/2} ${0}"/>
    <axis xyz="0.0 0.0 1"/>
  </joint>

  <link name="prop_3">
    <visual name="prop_3_link_visual">
      <geometry>
        <mesh filename="package://projet_robo_redev/meshes/1345_prop_ccw.stl"/>
      </geometry>
      <origin  rpy="0 0 0" xyz="-0.03 -0.17 0"/>
    </visual>
  </link> 

  <joint name="prop_to_arm_3" type="continuous">
    <parent link="arm_3"/>
    <child link="prop_3"/>
    <origin  rpy="0 0 0" xyz="${arm_len} ${arm_base/2} ${0}"/>
    <axis xyz="0.0 0.0 1"/>
  </joint>

  <link name="prop_4">
    <visual name="prop_4_link_visual">
      <geometry>
        <mesh filename="package://projet_robo_redev/meshes/1345_prop_cw.stl"/>
      </geometry>
      <origin  rpy="0 0 0" xyz="-0.03 -0.17 0"/>
    </visual>
  </link> 

  <joint name="prop_to_arm_4" type="continuous">
    <parent link="arm_4"/>
    <child link="prop_4"/>
    <origin  rpy="0 0 0" xyz="${arm_len} ${-arm_base/2} ${0}"/>
    <axis xyz="0.0 0.0 1"/>
  </joint>

</robot>